INFO 2025-10-02 07:56:20,965 autoreload Watching for file changes with StatReloader
ERROR 2025-10-02 07:56:27,565 log Internal Server Error: /admin/
Traceback (most recent call last):
  File "C:\Users\pmihu\AppData\Roaming\Python\Python312\site-packages\django\contrib\sessions\backends\file.py", line 31, in _get_storage_path
    return cls._storage_path
           ^^^^^^^^^^^^^^^^^
AttributeError: type object 'SessionStore' has no attribute '_storage_path'. Did you mean: '_get_storage_path'?

During handling of the above exception, another exception occurred:

Traceback (most recent call last):
  File "C:\Users\pmihu\AppData\Roaming\Python\Python312\site-packages\django\core\handlers\exception.py", line 55, in inner
    response = get_response(request)
               ^^^^^^^^^^^^^^^^^^^^^
  File "C:\Users\pmihu\AppData\Roaming\Python\Python312\site-packages\django\utils\deprecation.py", line 119, in __call__
    response = self.process_request(request)
               ^^^^^^^^^^^^^^^^^^^^^^^^^^^^^
  File "C:\Users\pmihu\AppData\Roaming\Python\Python312\site-packages\django\contrib\sessions\middleware.py", line 20, in process_request
    request.session = self.SessionStore(session_key)
                      ^^^^^^^^^^^^^^^^^^^^^^^^^^^^^^
  File "C:\Users\pmihu\AppData\Roaming\Python\Python312\site-packages\django\contrib\sessions\backends\file.py", line 24, in __init__
    self.storage_path = self._get_storage_path()
                        ^^^^^^^^^^^^^^^^^^^^^^^^
  File "C:\Users\pmihu\AppData\Roaming\Python\Python312\site-packages\django\contrib\sessions\backends\file.py", line 38, in _get_storage_path
    raise ImproperlyConfigured(
django.core.exceptions.ImproperlyConfigured: The session storage path WindowsPath('C:/Users/pmihu/OneDrive/Desktop/chobi/backend/sessions') doesn't exist. Please set your SESSION_FILE_PATH setting to an existing directory in which Django can store session data.
ERROR 2025-10-02 07:56:27,675 basehttp "GET /admin/ HTTP/1.1" 500 145
ERROR 2025-10-02 07:56:27,905 log Internal Server Error: /favicon.ico
Traceback (most recent call last):
  File "C:\Users\pmihu\AppData\Roaming\Python\Python312\site-packages\django\contrib\sessions\backends\file.py", line 31, in _get_storage_path
    return cls._storage_path
           ^^^^^^^^^^^^^^^^^
AttributeError: type object 'SessionStore' has no attribute '_storage_path'. Did you mean: '_get_storage_path'?

During handling of the above exception, another exception occurred:

Traceback (most recent call last):
  File "C:\Users\pmihu\AppData\Roaming\Python\Python312\site-packages\django\core\handlers\exception.py", line 55, in inner
    response = get_response(request)
               ^^^^^^^^^^^^^^^^^^^^^
  File "C:\Users\pmihu\AppData\Roaming\Python\Python312\site-packages\django\utils\deprecation.py", line 119, in __call__
    response = self.process_request(request)
               ^^^^^^^^^^^^^^^^^^^^^^^^^^^^^
  File "C:\Users\pmihu\AppData\Roaming\Python\Python312\site-packages\django\contrib\sessions\middleware.py", line 20, in process_request
    request.session = self.SessionStore(session_key)
                      ^^^^^^^^^^^^^^^^^^^^^^^^^^^^^^
  File "C:\Users\pmihu\AppData\Roaming\Python\Python312\site-packages\django\contrib\sessions\backends\file.py", line 24, in __init__
    self.storage_path = self._get_storage_path()
                        ^^^^^^^^^^^^^^^^^^^^^^^^
  File "C:\Users\pmihu\AppData\Roaming\Python\Python312\site-packages\django\contrib\sessions\backends\file.py", line 38, in _get_storage_path
    raise ImproperlyConfigured(
django.core.exceptions.ImproperlyConfigured: The session storage path WindowsPath('C:/Users/pmihu/OneDrive/Desktop/chobi/backend/sessions') doesn't exist. Please set your SESSION_FILE_PATH setting to an existing directory in which Django can store session data.
ERROR 2025-10-02 07:56:27,908 basehttp "GET /favicon.ico HTTP/1.1" 500 145
INFO 2025-10-02 07:57:09,741 autoreload Watching for file changes with StatReloader
ERROR 2025-10-02 07:57:13,906 log Internal Server Error: /admin/
Traceback (most recent call last):
  File "C:\Users\pmihu\AppData\Roaming\Python\Python312\site-packages\django\contrib\sessions\backends\file.py", line 31, in _get_storage_path
    return cls._storage_path
           ^^^^^^^^^^^^^^^^^
AttributeError: type object 'SessionStore' has no attribute '_storage_path'. Did you mean: '_get_storage_path'?

During handling of the above exception, another exception occurred:

Traceback (most recent call last):
  File "C:\Users\pmihu\AppData\Roaming\Python\Python312\site-packages\django\core\handlers\exception.py", line 55, in inner
    response = get_response(request)
               ^^^^^^^^^^^^^^^^^^^^^
  File "C:\Users\pmihu\AppData\Roaming\Python\Python312\site-packages\django\utils\deprecation.py", line 119, in __call__
    response = self.process_request(request)
               ^^^^^^^^^^^^^^^^^^^^^^^^^^^^^
  File "C:\Users\pmihu\AppData\Roaming\Python\Python312\site-packages\django\contrib\sessions\middleware.py", line 20, in process_request
    request.session = self.SessionStore(session_key)
                      ^^^^^^^^^^^^^^^^^^^^^^^^^^^^^^
  File "C:\Users\pmihu\AppData\Roaming\Python\Python312\site-packages\django\contrib\sessions\backends\file.py", line 24, in __init__
    self.storage_path = self._get_storage_path()
                        ^^^^^^^^^^^^^^^^^^^^^^^^
  File "C:\Users\pmihu\AppData\Roaming\Python\Python312\site-packages\django\contrib\sessions\backends\file.py", line 38, in _get_storage_path
    raise ImproperlyConfigured(
django.core.exceptions.ImproperlyConfigured: The session storage path WindowsPath('C:/Users/pmihu/OneDrive/Desktop/chobi/backend/sessions') doesn't exist. Please set your SESSION_FILE_PATH setting to an existing directory in which Django can store session data.
ERROR 2025-10-02 07:57:13,915 basehttp "GET /admin/ HTTP/1.1" 500 145
ERROR 2025-10-02 07:57:13,999 log Internal Server Error: /favicon.ico
Traceback (most recent call last):
  File "C:\Users\pmihu\AppData\Roaming\Python\Python312\site-packages\django\contrib\sessions\backends\file.py", line 31, in _get_storage_path
    return cls._storage_path
           ^^^^^^^^^^^^^^^^^
AttributeError: type object 'SessionStore' has no attribute '_storage_path'. Did you mean: '_get_storage_path'?

During handling of the above exception, another exception occurred:

Traceback (most recent call last):
  File "C:\Users\pmihu\AppData\Roaming\Python\Python312\site-packages\django\core\handlers\exception.py", line 55, in inner
    response = get_response(request)
               ^^^^^^^^^^^^^^^^^^^^^
  File "C:\Users\pmihu\AppData\Roaming\Python\Python312\site-packages\django\utils\deprecation.py", line 119, in __call__
    response = self.process_request(request)
               ^^^^^^^^^^^^^^^^^^^^^^^^^^^^^
  File "C:\Users\pmihu\AppData\Roaming\Python\Python312\site-packages\django\contrib\sessions\middleware.py", line 20, in process_request
    request.session = self.SessionStore(session_key)
                      ^^^^^^^^^^^^^^^^^^^^^^^^^^^^^^
  File "C:\Users\pmihu\AppData\Roaming\Python\Python312\site-packages\django\contrib\sessions\backends\file.py", line 24, in __init__
    self.storage_path = self._get_storage_path()
                        ^^^^^^^^^^^^^^^^^^^^^^^^
  File "C:\Users\pmihu\AppData\Roaming\Python\Python312\site-packages\django\contrib\sessions\backends\file.py", line 38, in _get_storage_path
    raise ImproperlyConfigured(
django.core.exceptions.ImproperlyConfigured: The session storage path WindowsPath('C:/Users/pmihu/OneDrive/Desktop/chobi/backend/sessions') doesn't exist. Please set your SESSION_FILE_PATH setting to an existing directory in which Django can store session data.
ERROR 2025-10-02 07:57:14,003 basehttp "GET /favicon.ico HTTP/1.1" 500 145
INFO 2025-10-02 07:58:37,296 autoreload Watching for file changes with StatReloader
ERROR 2025-10-02 07:58:41,575 log Internal Server Error: /admin/
Traceback (most recent call last):
  File "C:\Users\pmihu\AppData\Roaming\Python\Python312\site-packages\django\contrib\sessions\backends\file.py", line 31, in _get_storage_path
    return cls._storage_path
           ^^^^^^^^^^^^^^^^^
AttributeError: type object 'SessionStore' has no attribute '_storage_path'. Did you mean: '_get_storage_path'?

During handling of the above exception, another exception occurred:

Traceback (most recent call last):
  File "C:\Users\pmihu\AppData\Roaming\Python\Python312\site-packages\django\core\handlers\exception.py", line 55, in inner
    response = get_response(request)
               ^^^^^^^^^^^^^^^^^^^^^
  File "C:\Users\pmihu\AppData\Roaming\Python\Python312\site-packages\django\utils\deprecation.py", line 119, in __call__
    response = self.process_request(request)
               ^^^^^^^^^^^^^^^^^^^^^^^^^^^^^
  File "C:\Users\pmihu\AppData\Roaming\Python\Python312\site-packages\django\contrib\sessions\middleware.py", line 20, in process_request
    request.session = self.SessionStore(session_key)
                      ^^^^^^^^^^^^^^^^^^^^^^^^^^^^^^
  File "C:\Users\pmihu\AppData\Roaming\Python\Python312\site-packages\django\contrib\sessions\backends\file.py", line 24, in __init__
    self.storage_path = self._get_storage_path()
                        ^^^^^^^^^^^^^^^^^^^^^^^^
  File "C:\Users\pmihu\AppData\Roaming\Python\Python312\site-packages\django\contrib\sessions\backends\file.py", line 38, in _get_storage_path
    raise ImproperlyConfigured(
django.core.exceptions.ImproperlyConfigured: The session storage path WindowsPath('C:/Users/pmihu/OneDrive/Desktop/chobi/backend/sessions') doesn't exist. Please set your SESSION_FILE_PATH setting to an existing directory in which Django can store session data.
ERROR 2025-10-02 07:58:41,581 basehttp "GET /admin/ HTTP/1.1" 500 145
ERROR 2025-10-02 07:58:41,677 log Internal Server Error: /favicon.ico
Traceback (most recent call last):
  File "C:\Users\pmihu\AppData\Roaming\Python\Python312\site-packages\django\contrib\sessions\backends\file.py", line 31, in _get_storage_path
    return cls._storage_path
           ^^^^^^^^^^^^^^^^^
AttributeError: type object 'SessionStore' has no attribute '_storage_path'. Did you mean: '_get_storage_path'?

During handling of the above exception, another exception occurred:

Traceback (most recent call last):
  File "C:\Users\pmihu\AppData\Roaming\Python\Python312\site-packages\django\core\handlers\exception.py", line 55, in inner
    response = get_response(request)
               ^^^^^^^^^^^^^^^^^^^^^
  File "C:\Users\pmihu\AppData\Roaming\Python\Python312\site-packages\django\utils\deprecation.py", line 119, in __call__
    response = self.process_request(request)
               ^^^^^^^^^^^^^^^^^^^^^^^^^^^^^
  File "C:\Users\pmihu\AppData\Roaming\Python\Python312\site-packages\django\contrib\sessions\middleware.py", line 20, in process_request
    request.session = self.SessionStore(session_key)
                      ^^^^^^^^^^^^^^^^^^^^^^^^^^^^^^
  File "C:\Users\pmihu\AppData\Roaming\Python\Python312\site-packages\django\contrib\sessions\backends\file.py", line 24, in __init__
    self.storage_path = self._get_storage_path()
                        ^^^^^^^^^^^^^^^^^^^^^^^^
  File "C:\Users\pmihu\AppData\Roaming\Python\Python312\site-packages\django\contrib\sessions\backends\file.py", line 38, in _get_storage_path
    raise ImproperlyConfigured(
django.core.exceptions.ImproperlyConfigured: The session storage path WindowsPath('C:/Users/pmihu/OneDrive/Desktop/chobi/backend/sessions') doesn't exist. Please set your SESSION_FILE_PATH setting to an existing directory in which Django can store session data.
ERROR 2025-10-02 07:58:41,681 basehttp "GET /favicon.ico HTTP/1.1" 500 145
ERROR 2025-10-02 07:58:46,613 log Internal Server Error: /
Traceback (most recent call last):
  File "C:\Users\pmihu\AppData\Roaming\Python\Python312\site-packages\django\contrib\sessions\backends\file.py", line 31, in _get_storage_path
    return cls._storage_path
           ^^^^^^^^^^^^^^^^^
AttributeError: type object 'SessionStore' has no attribute '_storage_path'. Did you mean: '_get_storage_path'?

During handling of the above exception, another exception occurred:

Traceback (most recent call last):
  File "C:\Users\pmihu\AppData\Roaming\Python\Python312\site-packages\django\core\handlers\exception.py", line 55, in inner
    response = get_response(request)
               ^^^^^^^^^^^^^^^^^^^^^
  File "C:\Users\pmihu\AppData\Roaming\Python\Python312\site-packages\django\utils\deprecation.py", line 119, in __call__
    response = self.process_request(request)
               ^^^^^^^^^^^^^^^^^^^^^^^^^^^^^
  File "C:\Users\pmihu\AppData\Roaming\Python\Python312\site-packages\django\contrib\sessions\middleware.py", line 20, in process_request
    request.session = self.SessionStore(session_key)
                      ^^^^^^^^^^^^^^^^^^^^^^^^^^^^^^
  File "C:\Users\pmihu\AppData\Roaming\Python\Python312\site-packages\django\contrib\sessions\backends\file.py", line 24, in __init__
    self.storage_path = self._get_storage_path()
                        ^^^^^^^^^^^^^^^^^^^^^^^^
  File "C:\Users\pmihu\AppData\Roaming\Python\Python312\site-packages\django\contrib\sessions\backends\file.py", line 38, in _get_storage_path
    raise ImproperlyConfigured(
django.core.exceptions.ImproperlyConfigured: The session storage path WindowsPath('C:/Users/pmihu/OneDrive/Desktop/chobi/backend/sessions') doesn't exist. Please set your SESSION_FILE_PATH setting to an existing directory in which Django can store session data.
ERROR 2025-10-02 07:58:46,624 basehttp "GET / HTTP/1.1" 500 145
ERROR 2025-10-02 07:58:46,968 log Internal Server Error: /favicon.ico
Traceback (most recent call last):
  File "C:\Users\pmihu\AppData\Roaming\Python\Python312\site-packages\django\contrib\sessions\backends\file.py", line 31, in _get_storage_path
    return cls._storage_path
           ^^^^^^^^^^^^^^^^^
AttributeError: type object 'SessionStore' has no attribute '_storage_path'. Did you mean: '_get_storage_path'?

During handling of the above exception, another exception occurred:

Traceback (most recent call last):
  File "C:\Users\pmihu\AppData\Roaming\Python\Python312\site-packages\django\core\handlers\exception.py", line 55, in inner
    response = get_response(request)
               ^^^^^^^^^^^^^^^^^^^^^
  File "C:\Users\pmihu\AppData\Roaming\Python\Python312\site-packages\django\utils\deprecation.py", line 119, in __call__
    response = self.process_request(request)
               ^^^^^^^^^^^^^^^^^^^^^^^^^^^^^
  File "C:\Users\pmihu\AppData\Roaming\Python\Python312\site-packages\django\contrib\sessions\middleware.py", line 20, in process_request
    request.session = self.SessionStore(session_key)
                      ^^^^^^^^^^^^^^^^^^^^^^^^^^^^^^
  File "C:\Users\pmihu\AppData\Roaming\Python\Python312\site-packages\django\contrib\sessions\backends\file.py", line 24, in __init__
    self.storage_path = self._get_storage_path()
                        ^^^^^^^^^^^^^^^^^^^^^^^^
  File "C:\Users\pmihu\AppData\Roaming\Python\Python312\site-packages\django\contrib\sessions\backends\file.py", line 38, in _get_storage_path
    raise ImproperlyConfigured(
django.core.exceptions.ImproperlyConfigured: The session storage path WindowsPath('C:/Users/pmihu/OneDrive/Desktop/chobi/backend/sessions') doesn't exist. Please set your SESSION_FILE_PATH setting to an existing directory in which Django can store session data.
ERROR 2025-10-02 07:58:46,976 basehttp "GET /favicon.ico HTTP/1.1" 500 145
ERROR 2025-10-02 07:58:51,247 log Internal Server Error: /admin
Traceback (most recent call last):
  File "C:\Users\pmihu\AppData\Roaming\Python\Python312\site-packages\django\contrib\sessions\backends\file.py", line 31, in _get_storage_path
    return cls._storage_path
           ^^^^^^^^^^^^^^^^^
AttributeError: type object 'SessionStore' has no attribute '_storage_path'. Did you mean: '_get_storage_path'?

During handling of the above exception, another exception occurred:

Traceback (most recent call last):
  File "C:\Users\pmihu\AppData\Roaming\Python\Python312\site-packages\django\core\handlers\exception.py", line 55, in inner
    response = get_response(request)
               ^^^^^^^^^^^^^^^^^^^^^
  File "C:\Users\pmihu\AppData\Roaming\Python\Python312\site-packages\django\utils\deprecation.py", line 119, in __call__
    response = self.process_request(request)
               ^^^^^^^^^^^^^^^^^^^^^^^^^^^^^
  File "C:\Users\pmihu\AppData\Roaming\Python\Python312\site-packages\django\contrib\sessions\middleware.py", line 20, in process_request
    request.session = self.SessionStore(session_key)
                      ^^^^^^^^^^^^^^^^^^^^^^^^^^^^^^
  File "C:\Users\pmihu\AppData\Roaming\Python\Python312\site-packages\django\contrib\sessions\backends\file.py", line 24, in __init__
    self.storage_path = self._get_storage_path()
                        ^^^^^^^^^^^^^^^^^^^^^^^^
  File "C:\Users\pmihu\AppData\Roaming\Python\Python312\site-packages\django\contrib\sessions\backends\file.py", line 38, in _get_storage_path
    raise ImproperlyConfigured(
django.core.exceptions.ImproperlyConfigured: The session storage path WindowsPath('C:/Users/pmihu/OneDrive/Desktop/chobi/backend/sessions') doesn't exist. Please set your SESSION_FILE_PATH setting to an existing directory in which Django can store session data.
ERROR 2025-10-02 07:58:51,255 basehttp "GET /admin HTTP/1.1" 500 145
ERROR 2025-10-02 07:58:51,582 log Internal Server Error: /admin
Traceback (most recent call last):
  File "C:\Users\pmihu\AppData\Roaming\Python\Python312\site-packages\django\contrib\sessions\backends\file.py", line 31, in _get_storage_path
    return cls._storage_path
           ^^^^^^^^^^^^^^^^^
AttributeError: type object 'SessionStore' has no attribute '_storage_path'. Did you mean: '_get_storage_path'?

During handling of the above exception, another exception occurred:

Traceback (most recent call last):
  File "C:\Users\pmihu\AppData\Roaming\Python\Python312\site-packages\django\core\handlers\exception.py", line 55, in inner
    response = get_response(request)
               ^^^^^^^^^^^^^^^^^^^^^
  File "C:\Users\pmihu\AppData\Roaming\Python\Python312\site-packages\django\utils\deprecation.py", line 119, in __call__
    response = self.process_request(request)
               ^^^^^^^^^^^^^^^^^^^^^^^^^^^^^
  File "C:\Users\pmihu\AppData\Roaming\Python\Python312\site-packages\django\contrib\sessions\middleware.py", line 20, in process_request
    request.session = self.SessionStore(session_key)
                      ^^^^^^^^^^^^^^^^^^^^^^^^^^^^^^
  File "C:\Users\pmihu\AppData\Roaming\Python\Python312\site-packages\django\contrib\sessions\backends\file.py", line 24, in __init__
    self.storage_path = self._get_storage_path()
                        ^^^^^^^^^^^^^^^^^^^^^^^^
  File "C:\Users\pmihu\AppData\Roaming\Python\Python312\site-packages\django\contrib\sessions\backends\file.py", line 38, in _get_storage_path
    raise ImproperlyConfigured(
django.core.exceptions.ImproperlyConfigured: The session storage path WindowsPath('C:/Users/pmihu/OneDrive/Desktop/chobi/backend/sessions') doesn't exist. Please set your SESSION_FILE_PATH setting to an existing directory in which Django can store session data.
ERROR 2025-10-02 07:58:51,596 basehttp "GET /admin HTTP/1.1" 500 145
ERROR 2025-10-02 07:58:51,701 log Internal Server Error: /favicon.ico
Traceback (most recent call last):
  File "C:\Users\pmihu\AppData\Roaming\Python\Python312\site-packages\django\contrib\sessions\backends\file.py", line 31, in _get_storage_path
    return cls._storage_path
           ^^^^^^^^^^^^^^^^^
AttributeError: type object 'SessionStore' has no attribute '_storage_path'. Did you mean: '_get_storage_path'?

During handling of the above exception, another exception occurred:

Traceback (most recent call last):
  File "C:\Users\pmihu\AppData\Roaming\Python\Python312\site-packages\django\core\handlers\exception.py", line 55, in inner
    response = get_response(request)
               ^^^^^^^^^^^^^^^^^^^^^
  File "C:\Users\pmihu\AppData\Roaming\Python\Python312\site-packages\django\utils\deprecation.py", line 119, in __call__
    response = self.process_request(request)
               ^^^^^^^^^^^^^^^^^^^^^^^^^^^^^
  File "C:\Users\pmihu\AppData\Roaming\Python\Python312\site-packages\django\contrib\sessions\middleware.py", line 20, in process_request
    request.session = self.SessionStore(session_key)
                      ^^^^^^^^^^^^^^^^^^^^^^^^^^^^^^
  File "C:\Users\pmihu\AppData\Roaming\Python\Python312\site-packages\django\contrib\sessions\backends\file.py", line 24, in __init__
    self.storage_path = self._get_storage_path()
                        ^^^^^^^^^^^^^^^^^^^^^^^^
  File "C:\Users\pmihu\AppData\Roaming\Python\Python312\site-packages\django\contrib\sessions\backends\file.py", line 38, in _get_storage_path
    raise ImproperlyConfigured(
django.core.exceptions.ImproperlyConfigured: The session storage path WindowsPath('C:/Users/pmihu/OneDrive/Desktop/chobi/backend/sessions') doesn't exist. Please set your SESSION_FILE_PATH setting to an existing directory in which Django can store session data.
ERROR 2025-10-02 07:58:51,719 basehttp "GET /favicon.ico HTTP/1.1" 500 145
ERROR 2025-10-02 07:58:53,241 log Internal Server Error: /admin
Traceback (most recent call last):
  File "C:\Users\pmihu\AppData\Roaming\Python\Python312\site-packages\django\contrib\sessions\backends\file.py", line 31, in _get_storage_path
    return cls._storage_path
           ^^^^^^^^^^^^^^^^^
AttributeError: type object 'SessionStore' has no attribute '_storage_path'. Did you mean: '_get_storage_path'?

During handling of the above exception, another exception occurred:

Traceback (most recent call last):
  File "C:\Users\pmihu\AppData\Roaming\Python\Python312\site-packages\django\core\handlers\exception.py", line 55, in inner
    response = get_response(request)
               ^^^^^^^^^^^^^^^^^^^^^
  File "C:\Users\pmihu\AppData\Roaming\Python\Python312\site-packages\django\utils\deprecation.py", line 119, in __call__
    response = self.process_request(request)
               ^^^^^^^^^^^^^^^^^^^^^^^^^^^^^
  File "C:\Users\pmihu\AppData\Roaming\Python\Python312\site-packages\django\contrib\sessions\middleware.py", line 20, in process_request
    request.session = self.SessionStore(session_key)
                      ^^^^^^^^^^^^^^^^^^^^^^^^^^^^^^
  File "C:\Users\pmihu\AppData\Roaming\Python\Python312\site-packages\django\contrib\sessions\backends\file.py", line 24, in __init__
    self.storage_path = self._get_storage_path()
                        ^^^^^^^^^^^^^^^^^^^^^^^^
  File "C:\Users\pmihu\AppData\Roaming\Python\Python312\site-packages\django\contrib\sessions\backends\file.py", line 38, in _get_storage_path
    raise ImproperlyConfigured(
django.core.exceptions.ImproperlyConfigured: The session storage path WindowsPath('C:/Users/pmihu/OneDrive/Desktop/chobi/backend/sessions') doesn't exist. Please set your SESSION_FILE_PATH setting to an existing directory in which Django can store session data.
ERROR 2025-10-02 07:58:53,249 basehttp "GET /admin HTTP/1.1" 500 145
ERROR 2025-10-02 07:58:53,332 log Internal Server Error: /favicon.ico
Traceback (most recent call last):
  File "C:\Users\pmihu\AppData\Roaming\Python\Python312\site-packages\django\contrib\sessions\backends\file.py", line 31, in _get_storage_path
    return cls._storage_path
           ^^^^^^^^^^^^^^^^^
AttributeError: type object 'SessionStore' has no attribute '_storage_path'. Did you mean: '_get_storage_path'?

During handling of the above exception, another exception occurred:

Traceback (most recent call last):
  File "C:\Users\pmihu\AppData\Roaming\Python\Python312\site-packages\django\core\handlers\exception.py", line 55, in inner
    response = get_response(request)
               ^^^^^^^^^^^^^^^^^^^^^
  File "C:\Users\pmihu\AppData\Roaming\Python\Python312\site-packages\django\utils\deprecation.py", line 119, in __call__
    response = self.process_request(request)
               ^^^^^^^^^^^^^^^^^^^^^^^^^^^^^
  File "C:\Users\pmihu\AppData\Roaming\Python\Python312\site-packages\django\contrib\sessions\middleware.py", line 20, in process_request
    request.session = self.SessionStore(session_key)
                      ^^^^^^^^^^^^^^^^^^^^^^^^^^^^^^
  File "C:\Users\pmihu\AppData\Roaming\Python\Python312\site-packages\django\contrib\sessions\backends\file.py", line 24, in __init__
    self.storage_path = self._get_storage_path()
                        ^^^^^^^^^^^^^^^^^^^^^^^^
  File "C:\Users\pmihu\AppData\Roaming\Python\Python312\site-packages\django\contrib\sessions\backends\file.py", line 38, in _get_storage_path
    raise ImproperlyConfigured(
django.core.exceptions.ImproperlyConfigured: The session storage path WindowsPath('C:/Users/pmihu/OneDrive/Desktop/chobi/backend/sessions') doesn't exist. Please set your SESSION_FILE_PATH setting to an existing directory in which Django can store session data.
ERROR 2025-10-02 07:58:53,336 basehttp "GET /favicon.ico HTTP/1.1" 500 145
ERROR 2025-10-02 07:59:06,443 log Internal Server Error: /admin
Traceback (most recent call last):
  File "C:\Users\pmihu\AppData\Roaming\Python\Python312\site-packages\django\contrib\sessions\backends\file.py", line 31, in _get_storage_path
    return cls._storage_path
           ^^^^^^^^^^^^^^^^^
AttributeError: type object 'SessionStore' has no attribute '_storage_path'. Did you mean: '_get_storage_path'?

During handling of the above exception, another exception occurred:

Traceback (most recent call last):
  File "C:\Users\pmihu\AppData\Roaming\Python\Python312\site-packages\django\core\handlers\exception.py", line 55, in inner
    response = get_response(request)
               ^^^^^^^^^^^^^^^^^^^^^
  File "C:\Users\pmihu\AppData\Roaming\Python\Python312\site-packages\django\utils\deprecation.py", line 119, in __call__
    response = self.process_request(request)
               ^^^^^^^^^^^^^^^^^^^^^^^^^^^^^
  File "C:\Users\pmihu\AppData\Roaming\Python\Python312\site-packages\django\contrib\sessions\middleware.py", line 20, in process_request
    request.session = self.SessionStore(session_key)
                      ^^^^^^^^^^^^^^^^^^^^^^^^^^^^^^
  File "C:\Users\pmihu\AppData\Roaming\Python\Python312\site-packages\django\contrib\sessions\backends\file.py", line 24, in __init__
    self.storage_path = self._get_storage_path()
                        ^^^^^^^^^^^^^^^^^^^^^^^^
  File "C:\Users\pmihu\AppData\Roaming\Python\Python312\site-packages\django\contrib\sessions\backends\file.py", line 38, in _get_storage_path
    raise ImproperlyConfigured(
django.core.exceptions.ImproperlyConfigured: The session storage path WindowsPath('C:/Users/pmihu/OneDrive/Desktop/chobi/backend/sessions') doesn't exist. Please set your SESSION_FILE_PATH setting to an existing directory in which Django can store session data.
ERROR 2025-10-02 07:59:06,449 basehttp "GET /admin HTTP/1.1" 500 145
ERROR 2025-10-02 07:59:06,518 log Internal Server Error: /favicon.ico
Traceback (most recent call last):
  File "C:\Users\pmihu\AppData\Roaming\Python\Python312\site-packages\django\contrib\sessions\backends\file.py", line 31, in _get_storage_path
    return cls._storage_path
           ^^^^^^^^^^^^^^^^^
AttributeError: type object 'SessionStore' has no attribute '_storage_path'. Did you mean: '_get_storage_path'?

During handling of the above exception, another exception occurred:

Traceback (most recent call last):
  File "C:\Users\pmihu\AppData\Roaming\Python\Python312\site-packages\django\core\handlers\exception.py", line 55, in inner
    response = get_response(request)
               ^^^^^^^^^^^^^^^^^^^^^
  File "C:\Users\pmihu\AppData\Roaming\Python\Python312\site-packages\django\utils\deprecation.py", line 119, in __call__
    response = self.process_request(request)
               ^^^^^^^^^^^^^^^^^^^^^^^^^^^^^
  File "C:\Users\pmihu\AppData\Roaming\Python\Python312\site-packages\django\contrib\sessions\middleware.py", line 20, in process_request
    request.session = self.SessionStore(session_key)
                      ^^^^^^^^^^^^^^^^^^^^^^^^^^^^^^
  File "C:\Users\pmihu\AppData\Roaming\Python\Python312\site-packages\django\contrib\sessions\backends\file.py", line 24, in __init__
    self.storage_path = self._get_storage_path()
                        ^^^^^^^^^^^^^^^^^^^^^^^^
  File "C:\Users\pmihu\AppData\Roaming\Python\Python312\site-packages\django\contrib\sessions\backends\file.py", line 38, in _get_storage_path
    raise ImproperlyConfigured(
django.core.exceptions.ImproperlyConfigured: The session storage path WindowsPath('C:/Users/pmihu/OneDrive/Desktop/chobi/backend/sessions') doesn't exist. Please set your SESSION_FILE_PATH setting to an existing directory in which Django can store session data.
ERROR 2025-10-02 07:59:06,524 basehttp "GET /favicon.ico HTTP/1.1" 500 145
ERROR 2025-10-02 07:59:06,808 log Internal Server Error: /admin
Traceback (most recent call last):
  File "C:\Users\pmihu\AppData\Roaming\Python\Python312\site-packages\django\contrib\sessions\backends\file.py", line 31, in _get_storage_path
    return cls._storage_path
           ^^^^^^^^^^^^^^^^^
AttributeError: type object 'SessionStore' has no attribute '_storage_path'. Did you mean: '_get_storage_path'?

During handling of the above exception, another exception occurred:

Traceback (most recent call last):
  File "C:\Users\pmihu\AppData\Roaming\Python\Python312\site-packages\django\core\handlers\exception.py", line 55, in inner
    response = get_response(request)
               ^^^^^^^^^^^^^^^^^^^^^
  File "C:\Users\pmihu\AppData\Roaming\Python\Python312\site-packages\django\utils\deprecation.py", line 119, in __call__
    response = self.process_request(request)
               ^^^^^^^^^^^^^^^^^^^^^^^^^^^^^
  File "C:\Users\pmihu\AppData\Roaming\Python\Python312\site-packages\django\contrib\sessions\middleware.py", line 20, in process_request
    request.session = self.SessionStore(session_key)
                      ^^^^^^^^^^^^^^^^^^^^^^^^^^^^^^
  File "C:\Users\pmihu\AppData\Roaming\Python\Python312\site-packages\django\contrib\sessions\backends\file.py", line 24, in __init__
    self.storage_path = self._get_storage_path()
                        ^^^^^^^^^^^^^^^^^^^^^^^^
  File "C:\Users\pmihu\AppData\Roaming\Python\Python312\site-packages\django\contrib\sessions\backends\file.py", line 38, in _get_storage_path
    raise ImproperlyConfigured(
django.core.exceptions.ImproperlyConfigured: The session storage path WindowsPath('C:/Users/pmihu/OneDrive/Desktop/chobi/backend/sessions') doesn't exist. Please set your SESSION_FILE_PATH setting to an existing directory in which Django can store session data.
ERROR 2025-10-02 07:59:06,812 basehttp "GET /admin HTTP/1.1" 500 145
ERROR 2025-10-02 07:59:06,884 log Internal Server Error: /favicon.ico
Traceback (most recent call last):
  File "C:\Users\pmihu\AppData\Roaming\Python\Python312\site-packages\django\contrib\sessions\backends\file.py", line 31, in _get_storage_path
    return cls._storage_path
           ^^^^^^^^^^^^^^^^^
AttributeError: type object 'SessionStore' has no attribute '_storage_path'. Did you mean: '_get_storage_path'?

During handling of the above exception, another exception occurred:

Traceback (most recent call last):
  File "C:\Users\pmihu\AppData\Roaming\Python\Python312\site-packages\django\core\handlers\exception.py", line 55, in inner
    response = get_response(request)
               ^^^^^^^^^^^^^^^^^^^^^
  File "C:\Users\pmihu\AppData\Roaming\Python\Python312\site-packages\django\utils\deprecation.py", line 119, in __call__
    response = self.process_request(request)
               ^^^^^^^^^^^^^^^^^^^^^^^^^^^^^
  File "C:\Users\pmihu\AppData\Roaming\Python\Python312\site-packages\django\contrib\sessions\middleware.py", line 20, in process_request
    request.session = self.SessionStore(session_key)
                      ^^^^^^^^^^^^^^^^^^^^^^^^^^^^^^
  File "C:\Users\pmihu\AppData\Roaming\Python\Python312\site-packages\django\contrib\sessions\backends\file.py", line 24, in __init__
    self.storage_path = self._get_storage_path()
                        ^^^^^^^^^^^^^^^^^^^^^^^^
  File "C:\Users\pmihu\AppData\Roaming\Python\Python312\site-packages\django\contrib\sessions\backends\file.py", line 38, in _get_storage_path
    raise ImproperlyConfigured(
django.core.exceptions.ImproperlyConfigured: The session storage path WindowsPath('C:/Users/pmihu/OneDrive/Desktop/chobi/backend/sessions') doesn't exist. Please set your SESSION_FILE_PATH setting to an existing directory in which Django can store session data.
ERROR 2025-10-02 07:59:06,890 basehttp "GET /favicon.ico HTTP/1.1" 500 145
ERROR 2025-10-02 07:59:07,021 log Internal Server Error: /admin
Traceback (most recent call last):
  File "C:\Users\pmihu\AppData\Roaming\Python\Python312\site-packages\django\contrib\sessions\backends\file.py", line 31, in _get_storage_path
    return cls._storage_path
           ^^^^^^^^^^^^^^^^^
AttributeError: type object 'SessionStore' has no attribute '_storage_path'. Did you mean: '_get_storage_path'?

During handling of the above exception, another exception occurred:

Traceback (most recent call last):
  File "C:\Users\pmihu\AppData\Roaming\Python\Python312\site-packages\django\core\handlers\exception.py", line 55, in inner
    response = get_response(request)
               ^^^^^^^^^^^^^^^^^^^^^
  File "C:\Users\pmihu\AppData\Roaming\Python\Python312\site-packages\django\utils\deprecation.py", line 119, in __call__
    response = self.process_request(request)
               ^^^^^^^^^^^^^^^^^^^^^^^^^^^^^
  File "C:\Users\pmihu\AppData\Roaming\Python\Python312\site-packages\django\contrib\sessions\middleware.py", line 20, in process_request
    request.session = self.SessionStore(session_key)
                      ^^^^^^^^^^^^^^^^^^^^^^^^^^^^^^
  File "C:\Users\pmihu\AppData\Roaming\Python\Python312\site-packages\django\contrib\sessions\backends\file.py", line 24, in __init__
    self.storage_path = self._get_storage_path()
                        ^^^^^^^^^^^^^^^^^^^^^^^^
  File "C:\Users\pmihu\AppData\Roaming\Python\Python312\site-packages\django\contrib\sessions\backends\file.py", line 38, in _get_storage_path
    raise ImproperlyConfigured(
django.core.exceptions.ImproperlyConfigured: The session storage path WindowsPath('C:/Users/pmihu/OneDrive/Desktop/chobi/backend/sessions') doesn't exist. Please set your SESSION_FILE_PATH setting to an existing directory in which Django can store session data.
ERROR 2025-10-02 07:59:07,023 basehttp "GET /admin HTTP/1.1" 500 145
ERROR 2025-10-02 07:59:07,105 log Internal Server Error: /favicon.ico
Traceback (most recent call last):
  File "C:\Users\pmihu\AppData\Roaming\Python\Python312\site-packages\django\contrib\sessions\backends\file.py", line 31, in _get_storage_path
    return cls._storage_path
           ^^^^^^^^^^^^^^^^^
AttributeError: type object 'SessionStore' has no attribute '_storage_path'. Did you mean: '_get_storage_path'?

During handling of the above exception, another exception occurred:

Traceback (most recent call last):
  File "C:\Users\pmihu\AppData\Roaming\Python\Python312\site-packages\django\core\handlers\exception.py", line 55, in inner
    response = get_response(request)
               ^^^^^^^^^^^^^^^^^^^^^
  File "C:\Users\pmihu\AppData\Roaming\Python\Python312\site-packages\django\utils\deprecation.py", line 119, in __call__
    response = self.process_request(request)
               ^^^^^^^^^^^^^^^^^^^^^^^^^^^^^
  File "C:\Users\pmihu\AppData\Roaming\Python\Python312\site-packages\django\contrib\sessions\middleware.py", line 20, in process_request
    request.session = self.SessionStore(session_key)
                      ^^^^^^^^^^^^^^^^^^^^^^^^^^^^^^
  File "C:\Users\pmihu\AppData\Roaming\Python\Python312\site-packages\django\contrib\sessions\backends\file.py", line 24, in __init__
    self.storage_path = self._get_storage_path()
                        ^^^^^^^^^^^^^^^^^^^^^^^^
  File "C:\Users\pmihu\AppData\Roaming\Python\Python312\site-packages\django\contrib\sessions\backends\file.py", line 38, in _get_storage_path
    raise ImproperlyConfigured(
django.core.exceptions.ImproperlyConfigured: The session storage path WindowsPath('C:/Users/pmihu/OneDrive/Desktop/chobi/backend/sessions') doesn't exist. Please set your SESSION_FILE_PATH setting to an existing directory in which Django can store session data.
ERROR 2025-10-02 07:59:07,109 basehttp "GET /favicon.ico HTTP/1.1" 500 145
ERROR 2025-10-02 07:59:07,175 log Internal Server Error: /admin
Traceback (most recent call last):
  File "C:\Users\pmihu\AppData\Roaming\Python\Python312\site-packages\django\contrib\sessions\backends\file.py", line 31, in _get_storage_path
    return cls._storage_path
           ^^^^^^^^^^^^^^^^^
AttributeError: type object 'SessionStore' has no attribute '_storage_path'. Did you mean: '_get_storage_path'?

During handling of the above exception, another exception occurred:

Traceback (most recent call last):
  File "C:\Users\pmihu\AppData\Roaming\Python\Python312\site-packages\django\core\handlers\exception.py", line 55, in inner
    response = get_response(request)
               ^^^^^^^^^^^^^^^^^^^^^
  File "C:\Users\pmihu\AppData\Roaming\Python\Python312\site-packages\django\utils\deprecation.py", line 119, in __call__
    response = self.process_request(request)
               ^^^^^^^^^^^^^^^^^^^^^^^^^^^^^
  File "C:\Users\pmihu\AppData\Roaming\Python\Python312\site-packages\django\contrib\sessions\middleware.py", line 20, in process_request
    request.session = self.SessionStore(session_key)
                      ^^^^^^^^^^^^^^^^^^^^^^^^^^^^^^
  File "C:\Users\pmihu\AppData\Roaming\Python\Python312\site-packages\django\contrib\sessions\backends\file.py", line 24, in __init__
    self.storage_path = self._get_storage_path()
                        ^^^^^^^^^^^^^^^^^^^^^^^^
  File "C:\Users\pmihu\AppData\Roaming\Python\Python312\site-packages\django\contrib\sessions\backends\file.py", line 38, in _get_storage_path
    raise ImproperlyConfigured(
django.core.exceptions.ImproperlyConfigured: The session storage path WindowsPath('C:/Users/pmihu/OneDrive/Desktop/chobi/backend/sessions') doesn't exist. Please set your SESSION_FILE_PATH setting to an existing directory in which Django can store session data.
ERROR 2025-10-02 07:59:07,179 basehttp "GET /admin HTTP/1.1" 500 145
ERROR 2025-10-02 07:59:07,258 log Internal Server Error: /favicon.ico
Traceback (most recent call last):
  File "C:\Users\pmihu\AppData\Roaming\Python\Python312\site-packages\django\contrib\sessions\backends\file.py", line 31, in _get_storage_path
    return cls._storage_path
           ^^^^^^^^^^^^^^^^^
AttributeError: type object 'SessionStore' has no attribute '_storage_path'. Did you mean: '_get_storage_path'?

During handling of the above exception, another exception occurred:

Traceback (most recent call last):
  File "C:\Users\pmihu\AppData\Roaming\Python\Python312\site-packages\django\core\handlers\exception.py", line 55, in inner
    response = get_response(request)
               ^^^^^^^^^^^^^^^^^^^^^
  File "C:\Users\pmihu\AppData\Roaming\Python\Python312\site-packages\django\utils\deprecation.py", line 119, in __call__
    response = self.process_request(request)
               ^^^^^^^^^^^^^^^^^^^^^^^^^^^^^
  File "C:\Users\pmihu\AppData\Roaming\Python\Python312\site-packages\django\contrib\sessions\middleware.py", line 20, in process_request
    request.session = self.SessionStore(session_key)
                      ^^^^^^^^^^^^^^^^^^^^^^^^^^^^^^
  File "C:\Users\pmihu\AppData\Roaming\Python\Python312\site-packages\django\contrib\sessions\backends\file.py", line 24, in __init__
    self.storage_path = self._get_storage_path()
                        ^^^^^^^^^^^^^^^^^^^^^^^^
  File "C:\Users\pmihu\AppData\Roaming\Python\Python312\site-packages\django\contrib\sessions\backends\file.py", line 38, in _get_storage_path
    raise ImproperlyConfigured(
django.core.exceptions.ImproperlyConfigured: The session storage path WindowsPath('C:/Users/pmihu/OneDrive/Desktop/chobi/backend/sessions') doesn't exist. Please set your SESSION_FILE_PATH setting to an existing directory in which Django can store session data.
ERROR 2025-10-02 07:59:07,263 basehttp "GET /favicon.ico HTTP/1.1" 500 145
ERROR 2025-10-02 07:59:07,342 log Internal Server Error: /admin
Traceback (most recent call last):
  File "C:\Users\pmihu\AppData\Roaming\Python\Python312\site-packages\django\contrib\sessions\backends\file.py", line 31, in _get_storage_path
    return cls._storage_path
           ^^^^^^^^^^^^^^^^^
AttributeError: type object 'SessionStore' has no attribute '_storage_path'. Did you mean: '_get_storage_path'?

During handling of the above exception, another exception occurred:

Traceback (most recent call last):
  File "C:\Users\pmihu\AppData\Roaming\Python\Python312\site-packages\django\core\handlers\exception.py", line 55, in inner
    response = get_response(request)
               ^^^^^^^^^^^^^^^^^^^^^
  File "C:\Users\pmihu\AppData\Roaming\Python\Python312\site-packages\django\utils\deprecation.py", line 119, in __call__
    response = self.process_request(request)
               ^^^^^^^^^^^^^^^^^^^^^^^^^^^^^
  File "C:\Users\pmihu\AppData\Roaming\Python\Python312\site-packages\django\contrib\sessions\middleware.py", line 20, in process_request
    request.session = self.SessionStore(session_key)
                      ^^^^^^^^^^^^^^^^^^^^^^^^^^^^^^
  File "C:\Users\pmihu\AppData\Roaming\Python\Python312\site-packages\django\contrib\sessions\backends\file.py", line 24, in __init__
    self.storage_path = self._get_storage_path()
                        ^^^^^^^^^^^^^^^^^^^^^^^^
  File "C:\Users\pmihu\AppData\Roaming\Python\Python312\site-packages\django\contrib\sessions\backends\file.py", line 38, in _get_storage_path
    raise ImproperlyConfigured(
django.core.exceptions.ImproperlyConfigured: The session storage path WindowsPath('C:/Users/pmihu/OneDrive/Desktop/chobi/backend/sessions') doesn't exist. Please set your SESSION_FILE_PATH setting to an existing directory in which Django can store session data.
ERROR 2025-10-02 07:59:07,347 basehttp "GET /admin HTTP/1.1" 500 145
ERROR 2025-10-02 07:59:07,415 log Internal Server Error: /favicon.ico
Traceback (most recent call last):
  File "C:\Users\pmihu\AppData\Roaming\Python\Python312\site-packages\django\contrib\sessions\backends\file.py", line 31, in _get_storage_path
    return cls._storage_path
           ^^^^^^^^^^^^^^^^^
AttributeError: type object 'SessionStore' has no attribute '_storage_path'. Did you mean: '_get_storage_path'?

During handling of the above exception, another exception occurred:

Traceback (most recent call last):
  File "C:\Users\pmihu\AppData\Roaming\Python\Python312\site-packages\django\core\handlers\exception.py", line 55, in inner
    response = get_response(request)
               ^^^^^^^^^^^^^^^^^^^^^
  File "C:\Users\pmihu\AppData\Roaming\Python\Python312\site-packages\django\utils\deprecation.py", line 119, in __call__
    response = self.process_request(request)
               ^^^^^^^^^^^^^^^^^^^^^^^^^^^^^
  File "C:\Users\pmihu\AppData\Roaming\Python\Python312\site-packages\django\contrib\sessions\middleware.py", line 20, in process_request
    request.session = self.SessionStore(session_key)
                      ^^^^^^^^^^^^^^^^^^^^^^^^^^^^^^
  File "C:\Users\pmihu\AppData\Roaming\Python\Python312\site-packages\django\contrib\sessions\backends\file.py", line 24, in __init__
    self.storage_path = self._get_storage_path()
                        ^^^^^^^^^^^^^^^^^^^^^^^^
  File "C:\Users\pmihu\AppData\Roaming\Python\Python312\site-packages\django\contrib\sessions\backends\file.py", line 38, in _get_storage_path
    raise ImproperlyConfigured(
django.core.exceptions.ImproperlyConfigured: The session storage path WindowsPath('C:/Users/pmihu/OneDrive/Desktop/chobi/backend/sessions') doesn't exist. Please set your SESSION_FILE_PATH setting to an existing directory in which Django can store session data.
ERROR 2025-10-02 07:59:07,419 basehttp "GET /favicon.ico HTTP/1.1" 500 145
ERROR 2025-10-02 07:59:07,435 log Internal Server Error: /admin
Traceback (most recent call last):
  File "C:\Users\pmihu\AppData\Roaming\Python\Python312\site-packages\django\contrib\sessions\backends\file.py", line 31, in _get_storage_path
    return cls._storage_path
           ^^^^^^^^^^^^^^^^^
AttributeError: type object 'SessionStore' has no attribute '_storage_path'. Did you mean: '_get_storage_path'?

During handling of the above exception, another exception occurred:

Traceback (most recent call last):
  File "C:\Users\pmihu\AppData\Roaming\Python\Python312\site-packages\django\core\handlers\exception.py", line 55, in inner
    response = get_response(request)
               ^^^^^^^^^^^^^^^^^^^^^
  File "C:\Users\pmihu\AppData\Roaming\Python\Python312\site-packages\django\utils\deprecation.py", line 119, in __call__
    response = self.process_request(request)
               ^^^^^^^^^^^^^^^^^^^^^^^^^^^^^
  File "C:\Users\pmihu\AppData\Roaming\Python\Python312\site-packages\django\contrib\sessions\middleware.py", line 20, in process_request
    request.session = self.SessionStore(session_key)
                      ^^^^^^^^^^^^^^^^^^^^^^^^^^^^^^
  File "C:\Users\pmihu\AppData\Roaming\Python\Python312\site-packages\django\contrib\sessions\backends\file.py", line 24, in __init__
    self.storage_path = self._get_storage_path()
                        ^^^^^^^^^^^^^^^^^^^^^^^^
  File "C:\Users\pmihu\AppData\Roaming\Python\Python312\site-packages\django\contrib\sessions\backends\file.py", line 38, in _get_storage_path
    raise ImproperlyConfigured(
django.core.exceptions.ImproperlyConfigured: The session storage path WindowsPath('C:/Users/pmihu/OneDrive/Desktop/chobi/backend/sessions') doesn't exist. Please set your SESSION_FILE_PATH setting to an existing directory in which Django can store session data.
ERROR 2025-10-02 07:59:07,442 basehttp "GET /admin HTTP/1.1" 500 145
ERROR 2025-10-02 07:59:07,516 log Internal Server Error: /favicon.ico
Traceback (most recent call last):
  File "C:\Users\pmihu\AppData\Roaming\Python\Python312\site-packages\django\contrib\sessions\backends\file.py", line 31, in _get_storage_path
    return cls._storage_path
           ^^^^^^^^^^^^^^^^^
AttributeError: type object 'SessionStore' has no attribute '_storage_path'. Did you mean: '_get_storage_path'?

During handling of the above exception, another exception occurred:

Traceback (most recent call last):
  File "C:\Users\pmihu\AppData\Roaming\Python\Python312\site-packages\django\core\handlers\exception.py", line 55, in inner
    response = get_response(request)
               ^^^^^^^^^^^^^^^^^^^^^
  File "C:\Users\pmihu\AppData\Roaming\Python\Python312\site-packages\django\utils\deprecation.py", line 119, in __call__
    response = self.process_request(request)
               ^^^^^^^^^^^^^^^^^^^^^^^^^^^^^
  File "C:\Users\pmihu\AppData\Roaming\Python\Python312\site-packages\django\contrib\sessions\middleware.py", line 20, in process_request
    request.session = self.SessionStore(session_key)
                      ^^^^^^^^^^^^^^^^^^^^^^^^^^^^^^
  File "C:\Users\pmihu\AppData\Roaming\Python\Python312\site-packages\django\contrib\sessions\backends\file.py", line 24, in __init__
    self.storage_path = self._get_storage_path()
                        ^^^^^^^^^^^^^^^^^^^^^^^^
  File "C:\Users\pmihu\AppData\Roaming\Python\Python312\site-packages\django\contrib\sessions\backends\file.py", line 38, in _get_storage_path
    raise ImproperlyConfigured(
django.core.exceptions.ImproperlyConfigured: The session storage path WindowsPath('C:/Users/pmihu/OneDrive/Desktop/chobi/backend/sessions') doesn't exist. Please set your SESSION_FILE_PATH setting to an existing directory in which Django can store session data.
ERROR 2025-10-02 07:59:07,524 basehttp "GET /favicon.ico HTTP/1.1" 500 145
INFO 2025-10-02 08:00:20,595 autoreload Watching for file changes with StatReloader
ERROR 2025-10-02 08:00:25,107 log Internal Server Error: /admin
Traceback (most recent call last):
  File "C:\Users\pmihu\AppData\Roaming\Python\Python312\site-packages\django\contrib\sessions\backends\file.py", line 31, in _get_storage_path
    return cls._storage_path
           ^^^^^^^^^^^^^^^^^
AttributeError: type object 'SessionStore' has no attribute '_storage_path'. Did you mean: '_get_storage_path'?

During handling of the above exception, another exception occurred:

Traceback (most recent call last):
  File "C:\Users\pmihu\AppData\Roaming\Python\Python312\site-packages\django\core\handlers\exception.py", line 55, in inner
    response = get_response(request)
               ^^^^^^^^^^^^^^^^^^^^^
  File "C:\Users\pmihu\AppData\Roaming\Python\Python312\site-packages\django\utils\deprecation.py", line 119, in __call__
    response = self.process_request(request)
               ^^^^^^^^^^^^^^^^^^^^^^^^^^^^^
  File "C:\Users\pmihu\AppData\Roaming\Python\Python312\site-packages\django\contrib\sessions\middleware.py", line 20, in process_request
    request.session = self.SessionStore(session_key)
                      ^^^^^^^^^^^^^^^^^^^^^^^^^^^^^^
  File "C:\Users\pmihu\AppData\Roaming\Python\Python312\site-packages\django\contrib\sessions\backends\file.py", line 24, in __init__
    self.storage_path = self._get_storage_path()
                        ^^^^^^^^^^^^^^^^^^^^^^^^
  File "C:\Users\pmihu\AppData\Roaming\Python\Python312\site-packages\django\contrib\sessions\backends\file.py", line 38, in _get_storage_path
    raise ImproperlyConfigured(
django.core.exceptions.ImproperlyConfigured: The session storage path WindowsPath('C:/Users/pmihu/OneDrive/Desktop/chobi/backend/sessions') doesn't exist. Please set your SESSION_FILE_PATH setting to an existing directory in which Django can store session data.
ERROR 2025-10-02 08:00:25,111 basehttp "GET /admin HTTP/1.1" 500 145
ERROR 2025-10-02 08:00:25,375 log Internal Server Error: /favicon.ico
Traceback (most recent call last):
  File "C:\Users\pmihu\AppData\Roaming\Python\Python312\site-packages\django\contrib\sessions\backends\file.py", line 31, in _get_storage_path
    return cls._storage_path
           ^^^^^^^^^^^^^^^^^
AttributeError: type object 'SessionStore' has no attribute '_storage_path'. Did you mean: '_get_storage_path'?

During handling of the above exception, another exception occurred:

Traceback (most recent call last):
  File "C:\Users\pmihu\AppData\Roaming\Python\Python312\site-packages\django\core\handlers\exception.py", line 55, in inner
    response = get_response(request)
               ^^^^^^^^^^^^^^^^^^^^^
  File "C:\Users\pmihu\AppData\Roaming\Python\Python312\site-packages\django\utils\deprecation.py", line 119, in __call__
    response = self.process_request(request)
               ^^^^^^^^^^^^^^^^^^^^^^^^^^^^^
  File "C:\Users\pmihu\AppData\Roaming\Python\Python312\site-packages\django\contrib\sessions\middleware.py", line 20, in process_request
    request.session = self.SessionStore(session_key)
                      ^^^^^^^^^^^^^^^^^^^^^^^^^^^^^^
  File "C:\Users\pmihu\AppData\Roaming\Python\Python312\site-packages\django\contrib\sessions\backends\file.py", line 24, in __init__
    self.storage_path = self._get_storage_path()
                        ^^^^^^^^^^^^^^^^^^^^^^^^
  File "C:\Users\pmihu\AppData\Roaming\Python\Python312\site-packages\django\contrib\sessions\backends\file.py", line 38, in _get_storage_path
    raise ImproperlyConfigured(
django.core.exceptions.ImproperlyConfigured: The session storage path WindowsPath('C:/Users/pmihu/OneDrive/Desktop/chobi/backend/sessions') doesn't exist. Please set your SESSION_FILE_PATH setting to an existing directory in which Django can store session data.
ERROR 2025-10-02 08:00:25,384 basehttp "GET /favicon.ico HTTP/1.1" 500 145
ERROR 2025-10-02 08:00:26,414 log Internal Server Error: /admin
Traceback (most recent call last):
  File "C:\Users\pmihu\AppData\Roaming\Python\Python312\site-packages\django\contrib\sessions\backends\file.py", line 31, in _get_storage_path
    return cls._storage_path
           ^^^^^^^^^^^^^^^^^
AttributeError: type object 'SessionStore' has no attribute '_storage_path'. Did you mean: '_get_storage_path'?

During handling of the above exception, another exception occurred:

Traceback (most recent call last):
  File "C:\Users\pmihu\AppData\Roaming\Python\Python312\site-packages\django\core\handlers\exception.py", line 55, in inner
    response = get_response(request)
               ^^^^^^^^^^^^^^^^^^^^^
  File "C:\Users\pmihu\AppData\Roaming\Python\Python312\site-packages\django\utils\deprecation.py", line 119, in __call__
    response = self.process_request(request)
               ^^^^^^^^^^^^^^^^^^^^^^^^^^^^^
  File "C:\Users\pmihu\AppData\Roaming\Python\Python312\site-packages\django\contrib\sessions\middleware.py", line 20, in process_request
    request.session = self.SessionStore(session_key)
                      ^^^^^^^^^^^^^^^^^^^^^^^^^^^^^^
  File "C:\Users\pmihu\AppData\Roaming\Python\Python312\site-packages\django\contrib\sessions\backends\file.py", line 24, in __init__
    self.storage_path = self._get_storage_path()
                        ^^^^^^^^^^^^^^^^^^^^^^^^
  File "C:\Users\pmihu\AppData\Roaming\Python\Python312\site-packages\django\contrib\sessions\backends\file.py", line 38, in _get_storage_path
    raise ImproperlyConfigured(
django.core.exceptions.ImproperlyConfigured: The session storage path WindowsPath('C:/Users/pmihu/OneDrive/Desktop/chobi/backend/sessions') doesn't exist. Please set your SESSION_FILE_PATH setting to an existing directory in which Django can store session data.
ERROR 2025-10-02 08:00:26,420 basehttp "GET /admin HTTP/1.1" 500 145
ERROR 2025-10-02 08:00:26,512 log Internal Server Error: /favicon.ico
Traceback (most recent call last):
  File "C:\Users\pmihu\AppData\Roaming\Python\Python312\site-packages\django\contrib\sessions\backends\file.py", line 31, in _get_storage_path
    return cls._storage_path
           ^^^^^^^^^^^^^^^^^
AttributeError: type object 'SessionStore' has no attribute '_storage_path'. Did you mean: '_get_storage_path'?

During handling of the above exception, another exception occurred:

Traceback (most recent call last):
  File "C:\Users\pmihu\AppData\Roaming\Python\Python312\site-packages\django\core\handlers\exception.py", line 55, in inner
    response = get_response(request)
               ^^^^^^^^^^^^^^^^^^^^^
  File "C:\Users\pmihu\AppData\Roaming\Python\Python312\site-packages\django\utils\deprecation.py", line 119, in __call__
    response = self.process_request(request)
               ^^^^^^^^^^^^^^^^^^^^^^^^^^^^^
  File "C:\Users\pmihu\AppData\Roaming\Python\Python312\site-packages\django\contrib\sessions\middleware.py", line 20, in process_request
    request.session = self.SessionStore(session_key)
                      ^^^^^^^^^^^^^^^^^^^^^^^^^^^^^^
  File "C:\Users\pmihu\AppData\Roaming\Python\Python312\site-packages\django\contrib\sessions\backends\file.py", line 24, in __init__
    self.storage_path = self._get_storage_path()
                        ^^^^^^^^^^^^^^^^^^^^^^^^
  File "C:\Users\pmihu\AppData\Roaming\Python\Python312\site-packages\django\contrib\sessions\backends\file.py", line 38, in _get_storage_path
    raise ImproperlyConfigured(
django.core.exceptions.ImproperlyConfigured: The session storage path WindowsPath('C:/Users/pmihu/OneDrive/Desktop/chobi/backend/sessions') doesn't exist. Please set your SESSION_FILE_PATH setting to an existing directory in which Django can store session data.
ERROR 2025-10-02 08:00:26,514 basehttp "GET /favicon.ico HTTP/1.1" 500 145
ERROR 2025-10-02 08:00:27,119 log Internal Server Error: /admin
Traceback (most recent call last):
  File "C:\Users\pmihu\AppData\Roaming\Python\Python312\site-packages\django\contrib\sessions\backends\file.py", line 31, in _get_storage_path
    return cls._storage_path
           ^^^^^^^^^^^^^^^^^
AttributeError: type object 'SessionStore' has no attribute '_storage_path'. Did you mean: '_get_storage_path'?

During handling of the above exception, another exception occurred:

Traceback (most recent call last):
  File "C:\Users\pmihu\AppData\Roaming\Python\Python312\site-packages\django\core\handlers\exception.py", line 55, in inner
    response = get_response(request)
               ^^^^^^^^^^^^^^^^^^^^^
  File "C:\Users\pmihu\AppData\Roaming\Python\Python312\site-packages\django\utils\deprecation.py", line 119, in __call__
    response = self.process_request(request)
               ^^^^^^^^^^^^^^^^^^^^^^^^^^^^^
  File "C:\Users\pmihu\AppData\Roaming\Python\Python312\site-packages\django\contrib\sessions\middleware.py", line 20, in process_request
    request.session = self.SessionStore(session_key)
                      ^^^^^^^^^^^^^^^^^^^^^^^^^^^^^^
  File "C:\Users\pmihu\AppData\Roaming\Python\Python312\site-packages\django\contrib\sessions\backends\file.py", line 24, in __init__
    self.storage_path = self._get_storage_path()
                        ^^^^^^^^^^^^^^^^^^^^^^^^
  File "C:\Users\pmihu\AppData\Roaming\Python\Python312\site-packages\django\contrib\sessions\backends\file.py", line 38, in _get_storage_path
    raise ImproperlyConfigured(
django.core.exceptions.ImproperlyConfigured: The session storage path WindowsPath('C:/Users/pmihu/OneDrive/Desktop/chobi/backend/sessions') doesn't exist. Please set your SESSION_FILE_PATH setting to an existing directory in which Django can store session data.
ERROR 2025-10-02 08:00:27,122 basehttp "GET /admin HTTP/1.1" 500 145
ERROR 2025-10-02 08:00:27,195 log Internal Server Error: /favicon.ico
Traceback (most recent call last):
  File "C:\Users\pmihu\AppData\Roaming\Python\Python312\site-packages\django\contrib\sessions\backends\file.py", line 31, in _get_storage_path
    return cls._storage_path
           ^^^^^^^^^^^^^^^^^
AttributeError: type object 'SessionStore' has no attribute '_storage_path'. Did you mean: '_get_storage_path'?

During handling of the above exception, another exception occurred:

Traceback (most recent call last):
  File "C:\Users\pmihu\AppData\Roaming\Python\Python312\site-packages\django\core\handlers\exception.py", line 55, in inner
    response = get_response(request)
               ^^^^^^^^^^^^^^^^^^^^^
  File "C:\Users\pmihu\AppData\Roaming\Python\Python312\site-packages\django\utils\deprecation.py", line 119, in __call__
    response = self.process_request(request)
               ^^^^^^^^^^^^^^^^^^^^^^^^^^^^^
  File "C:\Users\pmihu\AppData\Roaming\Python\Python312\site-packages\django\contrib\sessions\middleware.py", line 20, in process_request
    request.session = self.SessionStore(session_key)
                      ^^^^^^^^^^^^^^^^^^^^^^^^^^^^^^
  File "C:\Users\pmihu\AppData\Roaming\Python\Python312\site-packages\django\contrib\sessions\backends\file.py", line 24, in __init__
    self.storage_path = self._get_storage_path()
                        ^^^^^^^^^^^^^^^^^^^^^^^^
  File "C:\Users\pmihu\AppData\Roaming\Python\Python312\site-packages\django\contrib\sessions\backends\file.py", line 38, in _get_storage_path
    raise ImproperlyConfigured(
django.core.exceptions.ImproperlyConfigured: The session storage path WindowsPath('C:/Users/pmihu/OneDrive/Desktop/chobi/backend/sessions') doesn't exist. Please set your SESSION_FILE_PATH setting to an existing directory in which Django can store session data.
ERROR 2025-10-02 08:00:27,202 basehttp "GET /favicon.ico HTTP/1.1" 500 145
ERROR 2025-10-02 08:00:27,804 log Internal Server Error: /admin
Traceback (most recent call last):
  File "C:\Users\pmihu\AppData\Roaming\Python\Python312\site-packages\django\contrib\sessions\backends\file.py", line 31, in _get_storage_path
    return cls._storage_path
           ^^^^^^^^^^^^^^^^^
AttributeError: type object 'SessionStore' has no attribute '_storage_path'. Did you mean: '_get_storage_path'?

During handling of the above exception, another exception occurred:

Traceback (most recent call last):
  File "C:\Users\pmihu\AppData\Roaming\Python\Python312\site-packages\django\core\handlers\exception.py", line 55, in inner
    response = get_response(request)
               ^^^^^^^^^^^^^^^^^^^^^
  File "C:\Users\pmihu\AppData\Roaming\Python\Python312\site-packages\django\utils\deprecation.py", line 119, in __call__
    response = self.process_request(request)
               ^^^^^^^^^^^^^^^^^^^^^^^^^^^^^
  File "C:\Users\pmihu\AppData\Roaming\Python\Python312\site-packages\django\contrib\sessions\middleware.py", line 20, in process_request
    request.session = self.SessionStore(session_key)
                      ^^^^^^^^^^^^^^^^^^^^^^^^^^^^^^
  File "C:\Users\pmihu\AppData\Roaming\Python\Python312\site-packages\django\contrib\sessions\backends\file.py", line 24, in __init__
    self.storage_path = self._get_storage_path()
                        ^^^^^^^^^^^^^^^^^^^^^^^^
  File "C:\Users\pmihu\AppData\Roaming\Python\Python312\site-packages\django\contrib\sessions\backends\file.py", line 38, in _get_storage_path
    raise ImproperlyConfigured(
django.core.exceptions.ImproperlyConfigured: The session storage path WindowsPath('C:/Users/pmihu/OneDrive/Desktop/chobi/backend/sessions') doesn't exist. Please set your SESSION_FILE_PATH setting to an existing directory in which Django can store session data.
ERROR 2025-10-02 08:00:27,809 basehttp "GET /admin HTTP/1.1" 500 145
ERROR 2025-10-02 08:00:27,890 log Internal Server Error: /favicon.ico
Traceback (most recent call last):
  File "C:\Users\pmihu\AppData\Roaming\Python\Python312\site-packages\django\contrib\sessions\backends\file.py", line 31, in _get_storage_path
    return cls._storage_path
           ^^^^^^^^^^^^^^^^^
AttributeError: type object 'SessionStore' has no attribute '_storage_path'. Did you mean: '_get_storage_path'?

During handling of the above exception, another exception occurred:

Traceback (most recent call last):
  File "C:\Users\pmihu\AppData\Roaming\Python\Python312\site-packages\django\core\handlers\exception.py", line 55, in inner
    response = get_response(request)
               ^^^^^^^^^^^^^^^^^^^^^
  File "C:\Users\pmihu\AppData\Roaming\Python\Python312\site-packages\django\utils\deprecation.py", line 119, in __call__
    response = self.process_request(request)
               ^^^^^^^^^^^^^^^^^^^^^^^^^^^^^
  File "C:\Users\pmihu\AppData\Roaming\Python\Python312\site-packages\django\contrib\sessions\middleware.py", line 20, in process_request
    request.session = self.SessionStore(session_key)
                      ^^^^^^^^^^^^^^^^^^^^^^^^^^^^^^
  File "C:\Users\pmihu\AppData\Roaming\Python\Python312\site-packages\django\contrib\sessions\backends\file.py", line 24, in __init__
    self.storage_path = self._get_storage_path()
                        ^^^^^^^^^^^^^^^^^^^^^^^^
  File "C:\Users\pmihu\AppData\Roaming\Python\Python312\site-packages\django\contrib\sessions\backends\file.py", line 38, in _get_storage_path
    raise ImproperlyConfigured(
django.core.exceptions.ImproperlyConfigured: The session storage path WindowsPath('C:/Users/pmihu/OneDrive/Desktop/chobi/backend/sessions') doesn't exist. Please set your SESSION_FILE_PATH setting to an existing directory in which Django can store session data.
ERROR 2025-10-02 08:00:27,894 basehttp "GET /favicon.ico HTTP/1.1" 500 145
ERROR 2025-10-02 08:00:30,086 log Internal Server Error: /admin/
Traceback (most recent call last):
  File "C:\Users\pmihu\AppData\Roaming\Python\Python312\site-packages\django\contrib\sessions\backends\file.py", line 31, in _get_storage_path
    return cls._storage_path
           ^^^^^^^^^^^^^^^^^
AttributeError: type object 'SessionStore' has no attribute '_storage_path'. Did you mean: '_get_storage_path'?

During handling of the above exception, another exception occurred:

Traceback (most recent call last):
  File "C:\Users\pmihu\AppData\Roaming\Python\Python312\site-packages\django\core\handlers\exception.py", line 55, in inner
    response = get_response(request)
               ^^^^^^^^^^^^^^^^^^^^^
  File "C:\Users\pmihu\AppData\Roaming\Python\Python312\site-packages\django\utils\deprecation.py", line 119, in __call__
    response = self.process_request(request)
               ^^^^^^^^^^^^^^^^^^^^^^^^^^^^^
  File "C:\Users\pmihu\AppData\Roaming\Python\Python312\site-packages\django\contrib\sessions\middleware.py", line 20, in process_request
    request.session = self.SessionStore(session_key)
                      ^^^^^^^^^^^^^^^^^^^^^^^^^^^^^^
  File "C:\Users\pmihu\AppData\Roaming\Python\Python312\site-packages\django\contrib\sessions\backends\file.py", line 24, in __init__
    self.storage_path = self._get_storage_path()
                        ^^^^^^^^^^^^^^^^^^^^^^^^
  File "C:\Users\pmihu\AppData\Roaming\Python\Python312\site-packages\django\contrib\sessions\backends\file.py", line 38, in _get_storage_path
    raise ImproperlyConfigured(
django.core.exceptions.ImproperlyConfigured: The session storage path WindowsPath('C:/Users/pmihu/OneDrive/Desktop/chobi/backend/sessions') doesn't exist. Please set your SESSION_FILE_PATH setting to an existing directory in which Django can store session data.
ERROR 2025-10-02 08:00:30,090 basehttp "GET /admin/ HTTP/1.1" 500 145
ERROR 2025-10-02 08:00:30,264 log Internal Server Error: /favicon.ico
Traceback (most recent call last):
  File "C:\Users\pmihu\AppData\Roaming\Python\Python312\site-packages\django\contrib\sessions\backends\file.py", line 31, in _get_storage_path
    return cls._storage_path
           ^^^^^^^^^^^^^^^^^
AttributeError: type object 'SessionStore' has no attribute '_storage_path'. Did you mean: '_get_storage_path'?

During handling of the above exception, another exception occurred:

Traceback (most recent call last):
  File "C:\Users\pmihu\AppData\Roaming\Python\Python312\site-packages\django\core\handlers\exception.py", line 55, in inner
    response = get_response(request)
               ^^^^^^^^^^^^^^^^^^^^^
  File "C:\Users\pmihu\AppData\Roaming\Python\Python312\site-packages\django\utils\deprecation.py", line 119, in __call__
    response = self.process_request(request)
               ^^^^^^^^^^^^^^^^^^^^^^^^^^^^^
  File "C:\Users\pmihu\AppData\Roaming\Python\Python312\site-packages\django\contrib\sessions\middleware.py", line 20, in process_request
    request.session = self.SessionStore(session_key)
                      ^^^^^^^^^^^^^^^^^^^^^^^^^^^^^^
  File "C:\Users\pmihu\AppData\Roaming\Python\Python312\site-packages\django\contrib\sessions\backends\file.py", line 24, in __init__
    self.storage_path = self._get_storage_path()
                        ^^^^^^^^^^^^^^^^^^^^^^^^
  File "C:\Users\pmihu\AppData\Roaming\Python\Python312\site-packages\django\contrib\sessions\backends\file.py", line 38, in _get_storage_path
    raise ImproperlyConfigured(
django.core.exceptions.ImproperlyConfigured: The session storage path WindowsPath('C:/Users/pmihu/OneDrive/Desktop/chobi/backend/sessions') doesn't exist. Please set your SESSION_FILE_PATH setting to an existing directory in which Django can store session data.
ERROR 2025-10-02 08:00:30,269 basehttp "GET /favicon.ico HTTP/1.1" 500 145
ERROR 2025-10-02 08:00:31,630 log Internal Server Error: /
Traceback (most recent call last):
  File "C:\Users\pmihu\AppData\Roaming\Python\Python312\site-packages\django\contrib\sessions\backends\file.py", line 31, in _get_storage_path
    return cls._storage_path
           ^^^^^^^^^^^^^^^^^
AttributeError: type object 'SessionStore' has no attribute '_storage_path'. Did you mean: '_get_storage_path'?

During handling of the above exception, another exception occurred:

Traceback (most recent call last):
  File "C:\Users\pmihu\AppData\Roaming\Python\Python312\site-packages\django\core\handlers\exception.py", line 55, in inner
    response = get_response(request)
               ^^^^^^^^^^^^^^^^^^^^^
  File "C:\Users\pmihu\AppData\Roaming\Python\Python312\site-packages\django\utils\deprecation.py", line 119, in __call__
    response = self.process_request(request)
               ^^^^^^^^^^^^^^^^^^^^^^^^^^^^^
  File "C:\Users\pmihu\AppData\Roaming\Python\Python312\site-packages\django\contrib\sessions\middleware.py", line 20, in process_request
    request.session = self.SessionStore(session_key)
                      ^^^^^^^^^^^^^^^^^^^^^^^^^^^^^^
  File "C:\Users\pmihu\AppData\Roaming\Python\Python312\site-packages\django\contrib\sessions\backends\file.py", line 24, in __init__
    self.storage_path = self._get_storage_path()
                        ^^^^^^^^^^^^^^^^^^^^^^^^
  File "C:\Users\pmihu\AppData\Roaming\Python\Python312\site-packages\django\contrib\sessions\backends\file.py", line 38, in _get_storage_path
    raise ImproperlyConfigured(
django.core.exceptions.ImproperlyConfigured: The session storage path WindowsPath('C:/Users/pmihu/OneDrive/Desktop/chobi/backend/sessions') doesn't exist. Please set your SESSION_FILE_PATH setting to an existing directory in which Django can store session data.
ERROR 2025-10-02 08:00:31,636 basehttp "GET / HTTP/1.1" 500 145
ERROR 2025-10-02 08:00:32,189 log Internal Server Error: /
Traceback (most recent call last):
  File "C:\Users\pmihu\AppData\Roaming\Python\Python312\site-packages\django\contrib\sessions\backends\file.py", line 31, in _get_storage_path
    return cls._storage_path
           ^^^^^^^^^^^^^^^^^
AttributeError: type object 'SessionStore' has no attribute '_storage_path'. Did you mean: '_get_storage_path'?

During handling of the above exception, another exception occurred:

Traceback (most recent call last):
  File "C:\Users\pmihu\AppData\Roaming\Python\Python312\site-packages\django\core\handlers\exception.py", line 55, in inner
    response = get_response(request)
               ^^^^^^^^^^^^^^^^^^^^^
  File "C:\Users\pmihu\AppData\Roaming\Python\Python312\site-packages\django\utils\deprecation.py", line 119, in __call__
    response = self.process_request(request)
               ^^^^^^^^^^^^^^^^^^^^^^^^^^^^^
  File "C:\Users\pmihu\AppData\Roaming\Python\Python312\site-packages\django\contrib\sessions\middleware.py", line 20, in process_request
    request.session = self.SessionStore(session_key)
                      ^^^^^^^^^^^^^^^^^^^^^^^^^^^^^^
  File "C:\Users\pmihu\AppData\Roaming\Python\Python312\site-packages\django\contrib\sessions\backends\file.py", line 24, in __init__
    self.storage_path = self._get_storage_path()
                        ^^^^^^^^^^^^^^^^^^^^^^^^
  File "C:\Users\pmihu\AppData\Roaming\Python\Python312\site-packages\django\contrib\sessions\backends\file.py", line 38, in _get_storage_path
    raise ImproperlyConfigured(
django.core.exceptions.ImproperlyConfigured: The session storage path WindowsPath('C:/Users/pmihu/OneDrive/Desktop/chobi/backend/sessions') doesn't exist. Please set your SESSION_FILE_PATH setting to an existing directory in which Django can store session data.
ERROR 2025-10-02 08:00:32,204 basehttp "GET / HTTP/1.1" 500 145
ERROR 2025-10-02 08:00:32,306 log Internal Server Error: /favicon.ico
Traceback (most recent call last):
  File "C:\Users\pmihu\AppData\Roaming\Python\Python312\site-packages\django\contrib\sessions\backends\file.py", line 31, in _get_storage_path
    return cls._storage_path
           ^^^^^^^^^^^^^^^^^
AttributeError: type object 'SessionStore' has no attribute '_storage_path'. Did you mean: '_get_storage_path'?

During handling of the above exception, another exception occurred:

Traceback (most recent call last):
  File "C:\Users\pmihu\AppData\Roaming\Python\Python312\site-packages\django\core\handlers\exception.py", line 55, in inner
    response = get_response(request)
               ^^^^^^^^^^^^^^^^^^^^^
  File "C:\Users\pmihu\AppData\Roaming\Python\Python312\site-packages\django\utils\deprecation.py", line 119, in __call__
    response = self.process_request(request)
               ^^^^^^^^^^^^^^^^^^^^^^^^^^^^^
  File "C:\Users\pmihu\AppData\Roaming\Python\Python312\site-packages\django\contrib\sessions\middleware.py", line 20, in process_request
    request.session = self.SessionStore(session_key)
                      ^^^^^^^^^^^^^^^^^^^^^^^^^^^^^^
  File "C:\Users\pmihu\AppData\Roaming\Python\Python312\site-packages\django\contrib\sessions\backends\file.py", line 24, in __init__
    self.storage_path = self._get_storage_path()
                        ^^^^^^^^^^^^^^^^^^^^^^^^
  File "C:\Users\pmihu\AppData\Roaming\Python\Python312\site-packages\django\contrib\sessions\backends\file.py", line 38, in _get_storage_path
    raise ImproperlyConfigured(
django.core.exceptions.ImproperlyConfigured: The session storage path WindowsPath('C:/Users/pmihu/OneDrive/Desktop/chobi/backend/sessions') doesn't exist. Please set your SESSION_FILE_PATH setting to an existing directory in which Django can store session data.
ERROR 2025-10-02 08:00:32,314 basehttp "GET /favicon.ico HTTP/1.1" 500 145
INFO 2025-10-02 08:06:34,994 autoreload Watching for file changes with StatReloader
ERROR 2025-10-02 08:06:38,970 log Internal Server Error: /
Traceback (most recent call last):
  File "C:\Users\pmihu\AppData\Roaming\Python\Python312\site-packages\django\contrib\sessions\backends\file.py", line 31, in _get_storage_path
    return cls._storage_path
           ^^^^^^^^^^^^^^^^^
AttributeError: type object 'SessionStore' has no attribute '_storage_path'. Did you mean: '_get_storage_path'?

During handling of the above exception, another exception occurred:

Traceback (most recent call last):
  File "C:\Users\pmihu\AppData\Roaming\Python\Python312\site-packages\django\core\handlers\exception.py", line 55, in inner
    response = get_response(request)
               ^^^^^^^^^^^^^^^^^^^^^
  File "C:\Users\pmihu\AppData\Roaming\Python\Python312\site-packages\django\utils\deprecation.py", line 119, in __call__
    response = self.process_request(request)
               ^^^^^^^^^^^^^^^^^^^^^^^^^^^^^
  File "C:\Users\pmihu\AppData\Roaming\Python\Python312\site-packages\django\contrib\sessions\middleware.py", line 20, in process_request
    request.session = self.SessionStore(session_key)
                      ^^^^^^^^^^^^^^^^^^^^^^^^^^^^^^
  File "C:\Users\pmihu\AppData\Roaming\Python\Python312\site-packages\django\contrib\sessions\backends\file.py", line 24, in __init__
    self.storage_path = self._get_storage_path()
                        ^^^^^^^^^^^^^^^^^^^^^^^^
  File "C:\Users\pmihu\AppData\Roaming\Python\Python312\site-packages\django\contrib\sessions\backends\file.py", line 38, in _get_storage_path
    raise ImproperlyConfigured(
django.core.exceptions.ImproperlyConfigured: The session storage path WindowsPath('C:/Users/pmihu/OneDrive/Desktop/chobi/backend/sessions') doesn't exist. Please set your SESSION_FILE_PATH setting to an existing directory in which Django can store session data.
ERROR 2025-10-02 08:06:38,977 basehttp "GET / HTTP/1.1" 500 145
ERROR 2025-10-02 08:06:39,037 log Internal Server Error: /
Traceback (most recent call last):
  File "C:\Users\pmihu\AppData\Roaming\Python\Python312\site-packages\django\contrib\sessions\backends\file.py", line 31, in _get_storage_path
    return cls._storage_path
           ^^^^^^^^^^^^^^^^^
AttributeError: type object 'SessionStore' has no attribute '_storage_path'. Did you mean: '_get_storage_path'?

During handling of the above exception, another exception occurred:

Traceback (most recent call last):
  File "C:\Users\pmihu\AppData\Roaming\Python\Python312\site-packages\django\core\handlers\exception.py", line 55, in inner
    response = get_response(request)
               ^^^^^^^^^^^^^^^^^^^^^
  File "C:\Users\pmihu\AppData\Roaming\Python\Python312\site-packages\django\utils\deprecation.py", line 119, in __call__
    response = self.process_request(request)
               ^^^^^^^^^^^^^^^^^^^^^^^^^^^^^
  File "C:\Users\pmihu\AppData\Roaming\Python\Python312\site-packages\django\contrib\sessions\middleware.py", line 20, in process_request
    request.session = self.SessionStore(session_key)
                      ^^^^^^^^^^^^^^^^^^^^^^^^^^^^^^
  File "C:\Users\pmihu\AppData\Roaming\Python\Python312\site-packages\django\contrib\sessions\backends\file.py", line 24, in __init__
    self.storage_path = self._get_storage_path()
                        ^^^^^^^^^^^^^^^^^^^^^^^^
  File "C:\Users\pmihu\AppData\Roaming\Python\Python312\site-packages\django\contrib\sessions\backends\file.py", line 38, in _get_storage_path
    raise ImproperlyConfigured(
django.core.exceptions.ImproperlyConfigured: The session storage path WindowsPath('C:/Users/pmihu/OneDrive/Desktop/chobi/backend/sessions') doesn't exist. Please set your SESSION_FILE_PATH setting to an existing directory in which Django can store session data.
ERROR 2025-10-02 08:06:39,041 basehttp "GET / HTTP/1.1" 500 145
ERROR 2025-10-02 08:06:39,299 log Internal Server Error: /favicon.ico
Traceback (most recent call last):
  File "C:\Users\pmihu\AppData\Roaming\Python\Python312\site-packages\django\contrib\sessions\backends\file.py", line 31, in _get_storage_path
    return cls._storage_path
           ^^^^^^^^^^^^^^^^^
AttributeError: type object 'SessionStore' has no attribute '_storage_path'. Did you mean: '_get_storage_path'?

During handling of the above exception, another exception occurred:

Traceback (most recent call last):
  File "C:\Users\pmihu\AppData\Roaming\Python\Python312\site-packages\django\core\handlers\exception.py", line 55, in inner
    response = get_response(request)
               ^^^^^^^^^^^^^^^^^^^^^
  File "C:\Users\pmihu\AppData\Roaming\Python\Python312\site-packages\django\utils\deprecation.py", line 119, in __call__
    response = self.process_request(request)
               ^^^^^^^^^^^^^^^^^^^^^^^^^^^^^
  File "C:\Users\pmihu\AppData\Roaming\Python\Python312\site-packages\django\contrib\sessions\middleware.py", line 20, in process_request
    request.session = self.SessionStore(session_key)
                      ^^^^^^^^^^^^^^^^^^^^^^^^^^^^^^
  File "C:\Users\pmihu\AppData\Roaming\Python\Python312\site-packages\django\contrib\sessions\backends\file.py", line 24, in __init__
    self.storage_path = self._get_storage_path()
                        ^^^^^^^^^^^^^^^^^^^^^^^^
  File "C:\Users\pmihu\AppData\Roaming\Python\Python312\site-packages\django\contrib\sessions\backends\file.py", line 38, in _get_storage_path
    raise ImproperlyConfigured(
django.core.exceptions.ImproperlyConfigured: The session storage path WindowsPath('C:/Users/pmihu/OneDrive/Desktop/chobi/backend/sessions') doesn't exist. Please set your SESSION_FILE_PATH setting to an existing directory in which Django can store session data.
ERROR 2025-10-02 08:06:39,314 basehttp "GET /favicon.ico HTTP/1.1" 500 145
INFO 2025-10-02 08:13:14,121 autoreload C:\Users\pmihu\OneDrive\Desktop\chobi\backend\chabighar_backend\settings.py changed, reloading.
INFO 2025-10-02 08:13:15,564 autoreload Watching for file changes with StatReloader
ERROR 2025-10-02 08:13:20,551 log Internal Server Error: /
Traceback (most recent call last):
  File "C:\Users\pmihu\AppData\Roaming\Python\Python312\site-packages\django\contrib\sessions\backends\file.py", line 31, in _get_storage_path
    return cls._storage_path
           ^^^^^^^^^^^^^^^^^
AttributeError: type object 'SessionStore' has no attribute '_storage_path'. Did you mean: '_get_storage_path'?

During handling of the above exception, another exception occurred:

Traceback (most recent call last):
  File "C:\Users\pmihu\AppData\Roaming\Python\Python312\site-packages\django\core\handlers\exception.py", line 55, in inner
    response = get_response(request)
               ^^^^^^^^^^^^^^^^^^^^^
  File "C:\Users\pmihu\AppData\Roaming\Python\Python312\site-packages\django\utils\deprecation.py", line 119, in __call__
    response = self.process_request(request)
               ^^^^^^^^^^^^^^^^^^^^^^^^^^^^^
  File "C:\Users\pmihu\AppData\Roaming\Python\Python312\site-packages\django\contrib\sessions\middleware.py", line 20, in process_request
    request.session = self.SessionStore(session_key)
                      ^^^^^^^^^^^^^^^^^^^^^^^^^^^^^^
  File "C:\Users\pmihu\AppData\Roaming\Python\Python312\site-packages\django\contrib\sessions\backends\file.py", line 24, in __init__
    self.storage_path = self._get_storage_path()
                        ^^^^^^^^^^^^^^^^^^^^^^^^
  File "C:\Users\pmihu\AppData\Roaming\Python\Python312\site-packages\django\contrib\sessions\backends\file.py", line 38, in _get_storage_path
    raise ImproperlyConfigured(
django.core.exceptions.ImproperlyConfigured: The session storage path WindowsPath('C:/Users/pmihu/OneDrive/Desktop/chobi/backend/sessions') doesn't exist. Please set your SESSION_FILE_PATH setting to an existing directory in which Django can store session data.
ERROR 2025-10-02 08:13:20,557 basehttp "GET / HTTP/1.1" 500 145
ERROR 2025-10-02 08:13:20,759 log Internal Server Error: /favicon.ico
Traceback (most recent call last):
  File "C:\Users\pmihu\AppData\Roaming\Python\Python312\site-packages\django\contrib\sessions\backends\file.py", line 31, in _get_storage_path
    return cls._storage_path
           ^^^^^^^^^^^^^^^^^
AttributeError: type object 'SessionStore' has no attribute '_storage_path'. Did you mean: '_get_storage_path'?

During handling of the above exception, another exception occurred:

Traceback (most recent call last):
  File "C:\Users\pmihu\AppData\Roaming\Python\Python312\site-packages\django\core\handlers\exception.py", line 55, in inner
    response = get_response(request)
               ^^^^^^^^^^^^^^^^^^^^^
  File "C:\Users\pmihu\AppData\Roaming\Python\Python312\site-packages\django\utils\deprecation.py", line 119, in __call__
    response = self.process_request(request)
               ^^^^^^^^^^^^^^^^^^^^^^^^^^^^^
  File "C:\Users\pmihu\AppData\Roaming\Python\Python312\site-packages\django\contrib\sessions\middleware.py", line 20, in process_request
    request.session = self.SessionStore(session_key)
                      ^^^^^^^^^^^^^^^^^^^^^^^^^^^^^^
  File "C:\Users\pmihu\AppData\Roaming\Python\Python312\site-packages\django\contrib\sessions\backends\file.py", line 24, in __init__
    self.storage_path = self._get_storage_path()
                        ^^^^^^^^^^^^^^^^^^^^^^^^
  File "C:\Users\pmihu\AppData\Roaming\Python\Python312\site-packages\django\contrib\sessions\backends\file.py", line 38, in _get_storage_path
    raise ImproperlyConfigured(
django.core.exceptions.ImproperlyConfigured: The session storage path WindowsPath('C:/Users/pmihu/OneDrive/Desktop/chobi/backend/sessions') doesn't exist. Please set your SESSION_FILE_PATH setting to an existing directory in which Django can store session data.
ERROR 2025-10-02 08:13:20,763 basehttp "GET /favicon.ico HTTP/1.1" 500 145
INFO 2025-10-02 08:14:00,133 autoreload C:\Users\pmihu\OneDrive\Desktop\chobi\backend\chabighar_backend\settings.py changed, reloading.
